Workbook

Sheet 2025
A1: PLANILLA URNI SEPTIEMBRE 2025
A2: N° | B2: FECHA NAC | C2: HORA | D2: Apellido Paterno RN | E2: NOMBRE COMPLETO MADRE DE RN | F2: RUT | G2: COMUNA | H2: CESFAM | I2: FECHA NAC MADRE | J2: TIPO DE PARTO | K2: E | L2: G | M2: SEXO | N2: 2480 | O2: Talla | P2: CC | Q2: Apego | R2: Lact antes 60' | S2: Profilaxis Ocular | T2: Vacuna Hepatitis B | U2: Profesional que vacuna VHB | V2: Vacuna BCG | W2: APGAR | Y2: Reanimación BÁSICA | Z2: Reanimación AVANZADA | AA2: Gases deCordón | AB2: APEGO CANGURO | AC2: APEGO TÚNEL | AD2: CLAMPEO TARDÍO | AE2: IVE CAUSAL 2 | AF2: MADRE VIH (+) | AG2: VDRL MATERNO | AI2: HEPATITIS B MATERNO | AK2: EDAD MATERNA | AL2: MIGRANTE | AM2: PUEBLO ORIGINARIO | AN2: DIAGNÓSTICO | AO2: MALFORMACION CONGÉNITA (SI/NO) | AP2: Describir malformación congénita | AQ2: Alojamiento Conjunto en Puerperio Inmediato | AR2: DESTINO RN | AS2: INTERNO | AT2: ACOMPAÑANTE EN PABELLON | AU2: OBSERVACIONES
K3: Sem | L3: Días | W3: 1' | X3: 5' | AG3: RESULTADO EXAMEN | AH3: TRATAMIENTO | AI3: RESULTADO EXAMEN | AJ3: PROFILAXIS COMPLETA SI/NO
A4: 1 | B4: 45901 | C4: 0.41388889 | G4: CHILLAN VIEJO | H4: FEDERICO PUGA | J4: CESAREA ELECTIVA | K4: 38 | L4: 2 | M4: FEMENINO | N4: 3450 | O4: 50 | P4: 35.5 | Q4: 4 | R4: SI | S4: SI | T4: SI | U4: KATHERINE RAMIREZ MEDINA | W4: 8 | X4: 9 | Y4: NO | Z4: NO | AA4: NO | AB4: SI | AC4: NO | AD4: SI | AE4: NO | AF4: NO | AG4: NO REACTIVO | AH4: NO | AI4: NEGATIVO | AJ4: NO | AK4: 27 | AL4: NO | AM4: NO | AN4: RNT 38 SEM AEG HMDIR | AO4: NO | AQ4: SI | AR4: RECUPERACION | AT4: SI
A5: 2 | B5: 45901 | C5: 0.49305556 | G5: CHILLAN | H5: SOL DE ORIENTE | J5: CESAREA ELECTIVA | K5: 39 | L5: 2 | M5: FEMENINO | N5: 3350 | O5: 50 | P5: 35 | Q5: 4 | R5: SI | S5: SI | T5: SI | U5: KATHERINE RAMIREZ MEDINA | W5: 8 | X5: 9 | Y5: NO | Z5: NO | AA5: NO | AB5: SI | AC5: NO | AD5: SI | AE5: NO | AF5: NO | AG5: NO REACTIVO | AH5: NO | AI5: NEGATIVO | AJ5: NO | AK5: 25 | AL5: NO | AM5: NO | AN5: RNT 39 SEM AEG | AO5: NO | AQ5: SI | AR5: RECUPERACION | AT5: SI
A6: 3 | B6: 45901 | C6: 0.6375 | G6: CHILLAN | H6: SOL DE ORIENTE | J6: EUTOCICO | K6: 39 | L6: 1 | M6: MASCULINO | N6: 3270 | O6: 49 | P6: 33 | Q6: 4 | R6: NO | S6: SI | T6: SI | U6: PATRICIA SANDOVAL | W6: 8 | X6: 9 | Y6: NO | Z6: NO | AA6: NO | AB6: N | AC6: NO | AD6: SI | AE6: NO | AF6: NO | AG6: NO REACTIVO | AH6: NO | AI6: NEGATIVO | AJ6: NO | AK6: 32 | AL6: SI | AM6: NO | AN6: RNT 39 SEM AEG OBS. CARDIOPATIA | AO6: NO | AQ6: NO | AR6: TIM NEO
A7: 4 | B7: 45901 | C7: 0.84305556 | G7: CHILLAN | H7: VIOLETA PARRA | J7: CESAREA URGENCIA | K7: 34 | L7: 6 | M7: MASCULINO | N7: 2470 | O7: 45 | P7: 33.5 | Q7: 4 | R7: SI | S7: SI | T7: SI | U7: CAMILA VERA | W7: 9 | X7: 9 | Y7: NO | Z7: NO | AA7: NO | AB7: NO | AC7: NO | AD7: SI | AE7: NO | AF7: NO | AG7: NO REACTIVO | AH7: NO | AI7: NEGATIVO | AJ7: NO | AK7: 36 | AL7: NO | AM7: NO | AN7: RNPT 34 AEG | AO7: NO | AQ7: SI | AR7: RECUPERACION
A8: 5 | B8: 45902 | C8: 0.15694444 | G8: PORTEZUELO | H8: PORTEZUELO | J8: EUTOCICO | K8: 41 | L8: 5 | M8: FEMENINO | N8: 4030 | O8: 50.5 | P8: 35.5 | Q8: 4 | R8: NO | S8: SI | T8: SI | U8: CAMILA VERA | W8: 8 | X8: 9 | Y8: NO | Z8: NO | AA8: NO | AB8: NO | AC8: NO | AD8: SI | AE8: NO | AF8: NO | AG8: NO REACTIVO | AH8: NO | AI8: NEGATIVO | AJ8: NO | AK8: 31 | AL8: NO | AM8: NO | AN8: RNT 41 SEM AEG | AO8: NO | AQ8: SI | AR8: SALA
A9: 6 | B9: 45902 | C9: 0.31805556 | G9: SAN IGNACIO | H9: PUEBLO SECO | J9: EUTOCICO | K9: 38 | L9: 6 | M9: FEMENINO | N9: 3660 | O9: 50.5 | P9: 35 | Q9: 4 | R9: SI | S9: SI | T9: SI | U9: ANA MENDEZ | W9: 9 | X9: 10 | Y9: NO | Z9: NO | AA9: NO | AB9: NO | AC9: NO | AD9: SI | AE9: NO | AF9: NO | AG9: NO REACTIVO | AH9: NO | AI9: NEGATIVO | AJ9: NO | AK9: 27 | AL9: NO | AM9: NO | AN9: RNT 38 SEM AEG | AO9: NO | AQ9: SI | AR9: SALA
A10: 7 | B10: 45902 | C10: 0.87083333 | G10: CHILLAN | H10: SAN RAMON NONATO | J10: EUTOCICO | K10: 36 | L10: 2 | M10: MASCULINO | N10: 2410 | O10: 45 | P10: 34 | Q10: 4 | R10: SI | S10: SI | T10: SI | U10: VALERIE HORSTMEIER | W10: 9 | X10: 10 | Y10: NO | Z10: NO | AA10: NO | AB10: NO | AC10: NO | AD10: SI | AE10: NO | AF10: NO | AG10: NO REACTIVO | AH10: NO | AI10: NEGATIVO | AJ10: NO | AK10: 21 | AL10: NO | AM10: NO | AN10: RNPT 36 SEM PEG | AO10: NO | AQ10: SI | AR10: SALA
A11: 8 | B11: 45903 | C11: 0.2875 | G11: CHILLAN | H11: VIOLETA PARRA | J11: EUTOCICO | K11: 39 | L11: 1 | M11: MASCULINO | N11: 3875 | O11: 50 | P11: 35 | Q11: 2 | R11: NO | S11: SI | T11: SI | U11: VALERIE HORSTMEIER | W11: 9 | X11: 10 | Y11: NO | Z11: NO | AA11: NO | AB11: NO | AC11: NO | AD11: SI | AE11: NO | AF11: NO | AG11: NO REACTIVO | AH11: NO | AI11: NEGATIVO | AJ11: NO | AK11: 42 | AL11: NO | AM11: NO | AN11: RNT 39 SEM AEG, SDR | AO11: NO | AQ11: SI | AR11: SALA
A12: 9 | B12: 45903 | C12: 0.4375 | G12: BULNES | H12: BULNES | J12: CESAREA ELECTIVA | K12: 37 | L12: 6 | M12: FEMENINO | N12: 3820 | O12: 52 | P12: 38 | Q12: 1 | R12: SI | S12: SI | T12: SI | U12: KATHERINE RAMIREZ MEDINA | W12: 7 | X12: 8 | Y12: SI | Z12: NO | AA12: NO | AB12: NO | AC12: NO | AD12: SI | AE12: NO | AF12: NO | AG12: NO REACTIVO | AH12: NO | AI12: NEGATIVO | AJ12: NO | AK12: 28 | AL12: NO | AM12: NO | AN12: RNT 37 SEM GEG | AO12: NO | AQ12: SI | AR12: RECUPERACION | AT12: NO
A13: 10 | B13: 45903 | C13: 0.4375 | G13: QUILLON | H13: QUILLON | J13: DISTOCICO | K13: 40 | L13: 4 | M13: MASCULINO | N13: 3310 | O13: 51.5 | P13: 35.5 | Q13: 4 | R13: SI | S13: SI | T13: SI | U13: FERNANDA VILCHES | W13: 8 | X13: 9 | Y13: NO | Z13: NO | AA13: NO | AB13: NO | AC13: NO | AD13: NO | AE13: NO | AF13: NO | AG13: NO REACTIVO | AH13: NO | AI13: NEGATIVO | AJ13: NO | AK13: 26 | AL13: NO | AM13: NO | AN13: RNT 40 SEM AEG, FRACTURA CLAVICULA DERECHA | AO13: NO | AQ13: SI | AR13: SALA
A14: 11 | B14: 45903 | C14: 0.47777778 | G14: COIHUECO | H14: COIHUECO | J14: EUTOCICO | K14: 38 | L14: 2 | M14: MASCULINO | N14: 3330 | O14: 48.5 | P14: 34 | Q14: 4 | R14: SI | S14: SI | T14: SI | U14: FERNANDA VILCHES | W14: 9 | X14: 10 | Y14: NO | Z14: NO | AA14: NO | AB14: NO | AC14: NO | AD14: SI | AE14: NO | AF14: NO | AG14: NO REACTIVO | AH14: NO | AI14: NEGATIVO | AJ14: NO | AK14: 15 | AL14: NO | AM14: NO | AN14: RNT 38 SEM AEG | AO14: NO | AQ14: SI | AR14: SALA
A15: 12 | B15: 45904 | C15: 0.045138889 | G15: YUNGAY | H15: YUNGAY | J15: CESAREA URGENCIA | K15: 37 | L15: 0 | M15: MASCULINO | N15: 2350 | O15: 46 | P15: 34 | Q15: 4 | R15: SI | S15: SI | T15: SI | U15: ANA MENDEZ | W15: 8 | X15: 9 | Y15: NO | Z15: NO | AA15: NO | AB15: SI | AC15: NO | AD15: SI | AE15: NO | AF15: NO | AG15: NO REACTIVO | AH15: NO | AI15: NEGATIVO | AJ15: NO | AK15: 24 | AL15: NO | AM15: NO | AN15: RNT 37 SEM PEG | AO15: NO | AQ15: SI | AR15: RECUPERACION | AT15: SI
A16: 13 | B16: 45904 | C16: 0.31944444 | G16: CHILLAN | H16: LOS VOLCANES | J16: CESAREA URGENCIA | K16: 36 | L16: 1 | M16: MASCULINO | N16: 2250 | O16: 47.5 | P16: 34 | Q16: 4 | R16: SI | S16: SI | T16: SI | U16: ANA MENDEZ | W16: 8 | X16: 9 | Y16: NO | Z16: NO | AA16: NO | AB16: SI | AC16: NO | AD16: SI | AE16: NO | AF16: NO | AG16: NO REACTIVO | AH16: NO | AI16: NEGATIVO | AJ16: NO | AK16: 41 | AL16: NO | AM16: NO | AN16: RNPT36 SEM PEG | AO16: NO | AQ16: SI | AR16: RECUPERACION | AT16: SI
A17: 14 | B17: 45904 | C17: 0.37569444 | G17: CHILLAN | H17: LOS VOLCANES | J17: EUTOCICO | K17: 40 | L17: 4 | M17: FEMENINO | N17: 3095 | O17: 49 | P17: 34 | Q17: 4 | R17: SI | S17: SI | T17: SI | U17: CAMILA VERA | W17: 9 | X17: 10 | Y17: NO | Z17: NO | AA17: NO | AB17: NO | AC17: NO | AD17: SI | AE17: NO | AF17: NO | AG17: NO REACTIVO | AH17: NO | AI17: NEGATIVO | AJ17: NO | AK17: 24 | AL17: NO | AM17: NO | AN17: RNT 40 SEM AEG | AO17: NO | AQ17: SI | AR17: SALA
A18: 15 | B18: 45904 | C18: 0.45 | G18: CHILLAN | H18: LOS VOLCANES | J18: EUTOCICO | K18: 38 | L18: 3 | M18: FEMENINO | N18: 2865 | O18: 50.5 | P18: 33 | Q18: 4 | R18: SI | S18: SI | T18: SI | U18: CAMILA VERA | W18: 9 | X18: 10 | Y18: NO | Z18: NO | AA18: NO | AB18: NO | AC18: NO | AD18: SI | AE18: NO | AF18: NO | AG18: NO REACTIVO | AH18: NO | AI18: NEGATIVO | AJ18: NO | AK18: 29 | AL18: NO | AM18: NO | AN18: RNT 38 SEM AEG | AO18: NO | AQ18: SI | AR18: SALA | AT18: NO
A19: 16 | B19: 45904 | C19: 0.45069444 | G19: CHILLAN | H19: LOS VOLCANES | J19: CESAREA ELECTIVA | K19: 38 | L19: 2 | M19: FEMENINO | N19: 2740 | O19: 46 | P19: 33 | Q19: 4 | R19: SI | S19: SI | T19: SI | U19: KATHERINE RAMIREZ MEDINA | W19: 9 | X19: 10 | Y19: NO | Z19: NO | AA19: NO | AB19: NO | AC19: SI | AD19: SI | AE19: NO | AF19: NO | AG19: NO REACTIVO | AH19: NO | AI19: NEGATIVO | AJ19: NO | AK19: 29 | AL19: NO | AM19: NO | AN19: RNT 38 SEM PEG | AO19: NO | AQ19: SI | AR19: RECUPERACION | AT19: NO
A20: 17 | B20: 45904 | C20: 0.49166667 | G20: CHILLAN | H20: VIOLETA PARRA | J20: EUTOCICO | K20: 39 | L20: 0 | M20: MASCULINO | N20: 3260 | O20: 49 | P20: 34 | Q20: 4 | R20: SI | S20: SI | T20: SI | U20: CAMILA VERA | W20: 9 | X20: 10 | Y20: NO | Z20: NO | AA20: NO | AB20: NO | AC20: NO | AD20: SI | AE20: NO | AF20: NO | AG20: NO REACTIVO | AH20: NO | AI20: NEGATIVO | AJ20: NO | AK20: 38 | AL20: NO | AM20: NO | AN20: RNT 39 AEG | AO20: NO | AQ20: SI | AR20: SALA
A21: 18 | B21: 45904 | C21: 0.55069444 | G21: CHILLÁN VIEJO | H21: FEDERICO PUGA | J21: CESAREA URGENCIA | K21: 38 | L21: 3 | M21: FEMENINO | N21: 3757 | O21: 50 | P21: 36.5 | Q21: 4 | R21: SI | S21: SI | T21: SI | U21: DANIEL DIONICIO | W21: 8 | X21: 9 | Y21: NO | Z21: NO | AA21: NO | AB21: SI | AC21: NO | AD21: NO | AE21: NO | AF21: NO | AG21: NO REACTIVO | AH21: NO | AI21: NEGATIVO | AJ21: NO | AK21: 28 | AL21: NO | AM21: NO | AN21: RN T 38 SEM GEG | AO21: NO | AQ21: SI | AR21: RECUPERACION | AT21: SI
A22: 19 | B22: 45905 | C22: 0.45 | G22: CHILLAN VIEJO | H22: MICHELLE BACHELET | J22: EUTOCICO | K22: 39 | L22: 1 | M22: FEMENINO | N22: 2970 | O22: 48 | P22: 34 | Q22: 4 | R22: SI | S22: SI | T22: SI | U22: CONSTANZA CANDIA | W22: 9 | X22: 10 | Y22: NO | Z22: NO | AA22: NO | AB22: NO | AC22: NO | AD22: SI | AE22: NO | AF22: NO | AG22: NO REACTIVO | AH22: NO | AI22: NEGATIVO | AJ22: NO | AK22: 32 | AL22: NO | AM22: NO | AN22: RNT 39 SEM AEG HMD C/DIETA | AO22: NO | AQ22: SI | AR22: SALA
A23: 20 | B23: 45905 | C23: 0.45277778 | G23: CHILLAN VIEJO | H23: ISABEL RIQUELME | J23: CESAREA ELECTIVA | K23: 38 | L23: 0 | M23: MASCULINO | N23: 3390 | O23: 49 | P23: 34 | Q23: 4 | R23: SI | S23: SI | T23: SI | U23: KATHERINE RAMIREZ MEDINA | W23: 9 | X23: 10 | Y23: NO | Z23: NO | AA23: NO | AB23: SI | AC23: SI | AD23: NO | AE23: NO | AF23: NO | AG23: NO REACTIVO | AH23: NO | AI23: NEGATIVO | AJ23: NO | AK23: 30 | AL23: NO | AM23: NO | AN23: RNT 38 SEM AEG HMD CON DIETA | AO23: NO | AQ23: SI | AR23: RECUPERACION | AT23: SI
A24: 21 | B24: 45905 | C24: 0.53680556 | G24: CHILLAN | H24: ULTRAESTACION | J24: CESAREA URGENCIA | K24: 40 | L24: 1 | M24: FEMENINO | N24: 3130 | O24: 48 | P24: 34 | Q24: 4 | R24: SI | S24: SI | T24: SI | U24: KATHERINE RAMIREZ MEDINA | W24: 9 | X24: 9 | Y24: NO | Z24: NO | AA24: NO | AB24: SI | AC24: NO | AD24: SI | AE24: NO | AF24: NO | AG24: NO REACTIVO | AH24: NO | AI24: NEGATIVO | AJ24: NO | AK24: 21 | AL24: NO | AM24: NO | AN24: RNT 40 SEM AEG HMD | AO24: NO | AQ24: SI | AR24: RECUPERACION | AT24: SI
A25: 22 | B25: 45905 | C25: 0.60972222 | G25: EL CARMEN | H25: EL CARMEN | J25: EUTOCICO | K25: 37 | L25: 6 | M25: MASCULINO | N25: 3360 | O25: 48 | P25: 34.5 | Q25: 4 | R25: SI | S25: SI | T25: SI | U25: CONSTANZA CANDIA | W25: 8 | X25: 8 | Y25: SI | Z25: NO | AA25: NO | AB25: SI | AC25: NO | AD25: SI | AE25: NO | AF25: NO | AG25: NO REACTIVO | AH25: NO | AI25: NEGATIVO | AJ25: NO | AK25: 25 | AL25: NO | AM25: NO | AN25: RNT 38 SEM AEG | AO25: NO | AQ25: SI | AR25: SALA
A26: 23 | B26: 45905 | C26: 0.65625 | G26: PUEBLO SECO | H26: PUEBLO SECO | J26: EUTOCICO | K26: 39 | L26: 0 | M26: FEMENINO | N26: 3370 | O26: 50 | P26: 34 | Q26: 4 | R26: SI | S26: SI | T26: SI | U26: CONSTANZA CANDIA | W26: 9 | X26: 9 | Y26: SI | Z26: NO | AA26: NO | AB26: NO | AC26: NO | AD26: SI | AE26: NO | AF26: NO | AG26: NO REACTIVO | AH26: NO | AI26: NEGATIVO | AJ26: NO | AK26: 34 | AL26: NO | AM26: NO | AN26: RNT 39 SEM AEG | AO26: NO | AQ26: SI | AR26: SALA
A27: 24 | B27: 45905 | C27: 0.78263889 | G27: CHILLAN | H27: MICHELLE BACHELET | J27: CESAREA URGENCIA | K27: 39 | L27: 1 | M27: FEMENINO | N27: 3360 | O27: 48.5 | P27: 36 | Q27: 4 | R27: SI | S27: SI | T27: SI | U27: CONSTANZA CANDIA | W27: 9 | X27: 10 | Y27: NO | Z27: NO | AA27: NO | AB27: NO | AC27: NO | AD27: SI | AE27: NO | AF27: NO | AG27: NO REACTIVO | AH27: NO | AI27: NEGATIVO | AJ27: NO | AK27: 23 | AL27: NO | AM27: NO | AN27: RNT 39 SEM SEG | AO27: NO | AQ27: SI | AR27: RECUPERACION | AT27: SI
A28: 25 | B28: 45783 | C28: 0.075694444 | G28: BULNES | H28: BULNES | J28: EUTOCICO | K28: 38 | L28: 3 | M28: FEMENINO | N28: 2820 | O28: 47.5 | P28: 35 | Q28: 4 | R28: SI | S28: SI | T28: SI | U28: CAMILA VERA | W28: 9 | X28: 10 | Y28: NO | Z28: NO | AA28: NO | AB28: N | AC28: NO | AD28: SI | AE28: NO | AF28: NO | AG28: NO REACTIVO | AH28: NO | AI28: NEGATIVO | AJ28: NO | AK28: 24 | AL28: NO | AM28: NO | AN28: RNT 38 AEG | AO28: NO | AQ28: SI | AR28: SALA
A29: 26 | B29: 45906 | C29: 0.59305556 | G29: CHILLAN | H29: SOL DE ORIENTE | J29: EUTOCICO | K29: 39 | L29: 0 | M29: MASCULINO | N29: 2580 | O29: 48 | P29: 35 | Q29: 4 | R29: SI | S29: SI | T29: SI | U29: ANA MENDEZ | W29: 8 | X29: 9 | Y29: NO | Z29: NO | AA29: NO | AB29: NO | AC29: NO | AD29: SI | AE29: NO | AF29: NO | AG29: NO REACTIVO | AH29: NO | AI29: NEGATIVO | AJ29: NO | AK29: 27 | AL29: NO | AM29: NO | AN29: RNT39 SEM PEG | AO29: NO | AQ29: SI | AR29: SALA
A30: 27 | B30: 45907 | C30: 0.43819444 | G30: CHILLAN | H30: SOL DE ORIENTE | J30: CESAREA URGENCIA | K30: 40 | L30: 1 | M30: MASCULINO | N30: 4170 | O30: 50 | P30: 37 | Q30: 4 | R30: SI | S30: SI | T30: SI | U30: FERNANDA VILCHES | W30: 8 | X30: 9 | Y30: NO | Z30: NO | AA30: NO | AB30: NO | AC30: NO | AD30: SI | AE30: NO | AF30: NO | AG30: NO REACTIVO | AH30: NO | AI30: NEGATIVO | AJ30: NO | AK30: 24 | AL30: NO | AM30: NO | AN30: RNT 40 SEM GEG, HMD | AO30: NO | AQ30: SI | AR30: RECUPERACION | AT30: SI
A31: 28 | B31: 45907 | C31: 0.88541667 | G31: RANQUIL | H31: ÑIPAS | J31: VACUUM | K31: EGD | M31: FEMENINO | N31: 2780 | O31: 48 | P31: 33 | Q31: 4 | R31: SI | S31: SI | T31: SI | U31: ANA MENDEZ | W31: 8 | X31: 9 | Y31: NO | Z31: NO | AA31: SI | AB31: NO | AC31: NO | AD31: SI | AE31: NO | AF31: NO | AG31: PENDIENTE | AH31: NO | AI31: S/P | AJ31: NO | AK31: 32 | AL31: NO | AM31: NO | AN31: RNT37 SEM AEG | AO31: NO | AQ31: SI | AR31: SALA
A32: 29 | B32: 45908 | C32: 0.24236111 | G32: CHILLAN | H32: VIOLETA PARRA | J32: EUTOCICO | K32: 36 | L32: 2 | M32: MASCULINO | N32: 3235 | O32: 49 | P32: 35.5 | Q32: 4 | R32: SI | S32: SI | T32: SI | U32: ANA MENDEZ | W32: 9 | X32: 9 | Y32: NO | Z32: NO | AA32: NO | AB32: NO | AC32: NO | AD32: SI | AE32: NO | AF32: NO | AG32: NO REACTIVO | AH32: NO | AI32: NEGATIVO | AJ32: NO | AK32: 34 | AL32: NO | AM32: NO | AN32: RNPT 36 SEM GEG | AO32: NO | AQ32: SI | AR32: SALA
A33: 30 | B33: 45908 | C33: 0.33055556 | G33: CHILLAN | H33: ISABEL RIQUELME | J33: EUTOCICO | K33: 39 | L33: 6 | M33: FEMENINO | N33: 3280 | O33: 49 | P33: 34 | Q33: 4 | R33: SI | S33: SI | T33: SI | U33: DANIELA NAVARRETE | W33: 9 | X33: 10 | Y33: NO | Z33: NO | AA33: NO | AB33: NO | AC33: NO | AD33: NO | AE33: NO | AF33: NO | AG33: NO REACTIVO | AH33: NO | AI33: NEGATIVO | AJ33: NO | AK33: 27 | AL33: NO | AM33: NO | AN33: RNT 39 SEM AEG | AO33: NO | AQ33: SI | AR33: SALA
A34: 31 | B34: 45908 | C34: 0.43263889 | G34: QUIRIHUE | H34: QUIRIHUE | J34: CESAREA ELECTIVA | K34: 40 | L34: 1 | M34: FEMENINO | N34: 3960 | O34: 52 | P34: 36 | Q34: 4 | R34: SI | S34: SI | T34: SI | U34: KATHERINE RAMIREZ MEDINA | W34: 9 | X34: 9 | Y34: NO | Z34: NO | AA34: NO | AB34: SI | AC34: SI | AD34: SI | AE34: NO | AF34: NO | AG34: NO REACTIVO | AH34: NO | AI34: NEGATIVO | AJ34: NO | AK34: 30 | AL34: NO | AM34: NO | AN34: RNT 40 SEM AEG HMD CON DIETA | AO34: NO | AQ34: SI | AR34: RECUPERACION | AT34: SI | AU34: 3 CIRCULAR AL CUELLO REDUCTIBLE
A35: 32 | B35: 45908 | C35: 0.49930556 | G35: COELEMU | H35: COELEMU | J35: CESAREA ELECTIVA | K35: 39 | L35: 4 | M35: MASCULINO | N35: 4290 | O35: 52 | P35: 35.5 | Q35: 4 | R35: SI | S35: SI | T35: SI | U35: KATHERINE RAMIREZ MEDINA | W35: 9 | X35: 10 | Y35: NO | Z35: NO | AA35: NO | AB35: SI | AC35: NO | AD35: SI | AE35: NO | AF35: NO | AG35: NO REACTIVO | AH35: NO | AI35: NEGATIVO | AJ35: NO | AK35: 27 | AL35: NO | AM35: NO | AN35: RNT 39 SEM GEG | AO35: NO | AQ35: SI | AR35: RECUPERACION | AT35: SI | AU35: 1 CIRCULAR AL CUELLO REDUCTIBLE
A36: 33 | B36: 45908 | C36: 0.55625 | G36: PUEBLO SECO | H36: VIOLETA PARRA | J36: EUTOCICO | K36: 38 | L36: 5 | M36: MASCULINO | N36: 3660 | O36: 49 | P36: 35 | Q36: 4 | R36: SI | S36: SI | T36: SI | U36: IGNACIO MATAMALA FLORES | W36: 9 | X36: 10 | Y36: NO | Z36: NO | AA36: NO | AB36: NO | AC36: NO | AD36: SI | AE36: NO | AF36: NO | AG36: NO REACTIVO | AH36: NO | AI36: NEGATIVO | AJ36: NO | AK36: 21 | AL36: NO | AM36: NO | AN36: RNT 38 SEM AEG | AO36: NO | AQ36: SI | AR36: SALA
A37: 34 | B37: 45908 | C37: 0.56111111 | G37: CHILLAN | H37: MICHELLE BACHELET | J37: EUTOCICO | K37: 38 | L37: 1 | M37: FEMENINO | N37: 3100 | O37: 46 | P37: 32 | Q37: 4 | R37: SI | S37: SI | T37: SI | U37: KATHERINE RAMIREZ MEDINA | W37: 8 | X37: 9 | Y37: NO | Z37: NO | AA37: NO | AB37: NO | AC37: NO | AD37: SI | AE37: NO | AF37: NO | AG37: NO REACTIVO | AH37: NO | AI37: NEGATIVO | AJ37: NO | AK37: 25 | AL37: NO | AM37: NO | AN37: RNT 38 SEM AEG | AO37: NO | AQ37: SI | AR37: SALA
A38: 35 | B38: 45908 | C38: 0.56736111 | G38: CHILLAN | H38: LOS VOLCANES | J38: EUTOCICO | K38: 34 | L38: 5 | M38: FEMENINO | N38: 2900 | O38: 46 | P38: 33.5 | Q38: 4 | R38: SI | S38: SI | T38: SI | U38: KATHERINE RAMIREZ MEDINA | W38: 9 | X38: 9 | Y38: NO | Z38: NO | AA38: NO | AB38: NO | AC38: NO | AD38: SI | AE38: NO | AF38: NO | AG38: NO REACTIVO | AH38: NO | AI38: NEGATIVO | AJ38: NO | AK38: 23 | AL38: NO | AM38: NO | AN38: RNT 35 SEM AEG | AO38: NO | AQ38: SI | AR38: TIM NEO
A39: 36 | B39: 45908 | C39: 0.61458333 | G39: CHILLAN | H39: PARTICULAR | J39: CESAREA URGENCIA | K39: 24 | L39: 6 | M39: MASCULINO | N39: 880 | O39: 33 | P39: 23.5 | Q39: 1 | R39: NO | S39: SI | T39: SI | U39: KATHERINE RAMIREZ/CAMILA VERA | W39: 1 | X39: 5 | Y39: SI | Z39: SI | AA39: NO | AB39: NO | AC39: NO | AD39: NO | AE39: NO | AF39: NO | AG39: NO REACTIVO | AH39: NO | AI39: NEGATIVO | AJ39: NO | AK39: 34 | AL39: NO | AM39: NO | AN39: RNPT 25 AEG, SDR EN EVOLUCION | AO39: NO | AQ39: SI | AR39: UCI | AT39: NO
A40: 37 | B40: 45909 | C40: 0.072916667 | G40: CHILLAN | H40: VIOLETA PARRA | J40: EUTOCICO | K40: 39 | L40: 1 | M40: FEMENINO | N40: 3080 | O40: 49 | P40: 34 | Q40: 4 | R40: SI | S40: SI | T40: SI | U40: FERNANDA VILCHES | W40: 9 | X40: 10 | Y40: NO | Z40: NO | AA40: NO | AB40: NO | AC40: NO | AD40: SI | AE40: NO | AF40: NO | AG40: NO REACTIVO | AH40: NO | AI40: NEGATIVO | AJ40: NO | AK40: 38 | AL40: NO | AM40: NO | AN40: RNT 39 SEM AEG | AO40: NO | AQ40: SI | AR40: SALA
...

Sheet BCG (2)
A1: VACUNA BCG
A2: N° | B2: NOMBRE COMPLETO MADRE DE RN | C2: RUT | D2: si/no | E2: Comuna | F2: Fecha Nacimiento Madre | G2: Fecha Nacimiento Hijo | H2: Sexo | I2: Peso | J2: Reacción Adversa | K2: N° Cama
A3: ='2025'!A4 -> 1 | B3: ='2025'!E4 -> 0 | C3: ='2025'!F4 -> 0 | D3: si | E3: ='2025'!G4 -> CHILLAN VIEJO | F3: ='2025'!I4 -> 0 | G3: ='2025'!B4 -> 45901 | H3: ='2025'!M4 -> FEMENINO | I3: ='2025'!N4 -> 3450
A4: ='2025'!A5 -> 2 | B4: ='2025'!E5 -> 0 | C4: ='2025'!F5 -> 0 | D4: no | E4: ='2025'!G5 -> CHILLAN | F4: ='2025'!I5 -> 0 | G4: ='2025'!B5 -> 45901 | H4: ='2025'!M5 -> FEMENINO | I4: ='2025'!N5 -> 3350
A5: ='2025'!A6 -> 3 | B5: ='2025'!E6 -> 0 | C5: ='2025'!F6 -> 0 | D5: no | E5: ='2025'!G6 -> CHILLAN | F5: ='2025'!I6 -> 0 | G5: ='2025'!B6 -> 45901 | H5: ='2025'!M6 -> MASCULINO | I5: ='2025'!N6 -> 3270
A6: ='2025'!A7 -> 4 | B6: ='2025'!E7 -> 0 | C6: ='2025'!F7 -> 0 | D6: si | E6: ='2025'!G7 -> CHILLAN | F6: ='2025'!I7 -> 0 | G6: ='2025'!B7 -> 45901 | H6: ='2025'!M7 -> MASCULINO | I6: ='2025'!N7 -> 2470
A7: ='2025'!A8 -> 5 | B7: ='2025'!E8 -> 0 | C7: ='2025'!F8 -> 0 | D7: si | E7: ='2025'!G8 -> PORTEZUELO | F7: ='2025'!I8 -> 0 | G7: ='2025'!B8 -> 45902 | H7: ='2025'!M8 -> FEMENINO | I7: ='2025'!N8 -> 4030
A8: ='2025'!A9 -> 6 | B8: ='2025'!E9 -> 0 | C8: ='2025'!F9 -> 0 | D8: si | E8: ='2025'!G9 -> SAN IGNACIO | F8: ='2025'!I9 -> 0 | G8: ='2025'!B9 -> 45902 | H8: ='2025'!M9 -> FEMENINO | I8: ='2025'!N9 -> 3660
A9: ='2025'!A10 -> 7 | B9: ='2025'!E10 -> 0 | C9: ='2025'!F10 -> 0 | D9: si | E9: ='2025'!G10 -> CHILLAN | F9: ='2025'!I10 -> 0 | G9: ='2025'!B10 -> 45902 | H9: ='2025'!M10 -> MASCULINO | I9: ='2025'!N10 -> 2410
A10: ='2025'!A11 -> 8 | B10: ='2025'!E11 -> 0 | C10: ='2025'!F11 -> 0 | D10: si | E10: ='2025'!G11 -> CHILLAN | F10: ='2025'!I11 -> 0 | G10: ='2025'!B11 -> 45903 | H10: ='2025'!M11 -> MASCULINO | I10: ='2025'!N11 -> 3875
A11: ='2025'!A12 -> 9 | B11: ='2025'!E12 -> 0 | C11: ='2025'!F12 -> 0 | D11: si | E11: ='2025'!G12 -> BULNES | F11: ='2025'!I12 -> 0 | G11: ='2025'!B12 -> 45903 | H11: ='2025'!M12 -> FEMENINO | I11: ='2025'!N12 -> 3820
A12: ='2025'!A13 -> 10 | B12: ='2025'!E13 -> 0 | C12: ='2025'!F13 -> 0 | D12: si | E12: ='2025'!G13 -> QUILLON | F12: ='2025'!I13 -> 0 | G12: ='2025'!B13 -> 45903 | H12: ='2025'!M13 -> MASCULINO | I12: ='2025'!N13 -> 3310
A13: ='2025'!A14 -> 11 | B13: ='2025'!E14 -> 0 | C13: ='2025'!F14 -> 0 | D13: si | E13: ='2025'!G14 -> COIHUECO | F13: ='2025'!I14 -> 0 | G13: ='2025'!B14 -> 45903 | H13: ='2025'!M14 -> MASCULINO | I13: ='2025'!N14 -> 3330
A14: ='2025'!A15 -> 12 | B14: ='2025'!E15 -> 0 | C14: ='2025'!F15 -> 0 | D14: si | E14: ='2025'!G15 -> YUNGAY | F14: ='2025'!I15 -> 0 | G14: ='2025'!B15 -> 45904 | H14: ='2025'!M15 -> MASCULINO | I14: ='2025'!N15 -> 2350
... A34: ='2025'!A35 -> 32 | B34: ='2025'!E35 -> 0 | C34: ='2025'!F35 -> 0 | D34: si | E34: ='2025'!G35 -> COELEMU | F34: ='2025'!I35 -> 0 | G34: ='2025'!B35 -> 45908 | H34: ='2025'!M35 -> MASCULINO | I34: ='2025'!N35 -> 4290
A35: ='2025'!#REF! -> #REF! | B35: ='2025'!E36 -> 0 | C35: ='2025'!F36 -> 0 | D35: si | E35: ='2025'!G36 -> PUEBLO SECO | F35: ='2025'!I36 -> 0 | G35: ='2025'!B36 -> 45908 | H35: ='2025'!M36 -> MASCULINO | I35: ='2025'!N36 -> 3660
A36: ='2025'!A39 -> 36 | B36: ='2025'!#REF! -> #REF! | C36: ='2025'!#REF! -> #REF! | D36: si | E36: ='2025'!#REF! -> #REF! | F36: ='2025'!#REF! -> #REF! | G36: ='2025'!#REF! -> #REF! | H36: ='2025'!#REF! -> #REF! | I36: ='2025'!#REF! -> #REF!
A37: ='2025'!A40 -> 37 | B37: ='2025'!E39 -> 0 | C37: ='2025'!F39 -> 0 | D37: si | E37: ='2025'!G39 -> CHILLAN | F37: ='2025'!I39 -> 0 | G37: ='2025'!B39 -> 45908 | H37: ='2025'!M39 -> MASCULINO | I37: ='2025'!N39 -> 880
A38: ='2025'!A41 -> 38 | B38: ='2025'!E40 -> 0 | C38: ='2025'!F40 -> 0 | D38: si | E38: ='2025'!G40 -> CHILLAN | F38: ='2025'!I40 -> 0 | G38: ='2025'!B40 -> 45909 | H38: ='2025'!M40 -> FEMENINO | I38: ='2025'!N40 -> 3080
A39: ='2025'!A42 -> 39 | B39: ='2025'!E41 -> 0 | C39: ='2025'!F41 -> 0 | D39: si | E39: ='2025'!G41 -> YUNGAY | F39: ='2025'!I41 -> 0 | G39: ='2025'!B42 -> 45909 | H39: ='2025'!M41 -> MASCULINO | I39: ='2025'!N41 -> 2650
A40: ='2025'!A43 -> 40 | B40: ='2025'!E42 -> 0 | C40: ='2025'!F42 -> 0 | D40: si | E40: ='2025'!G42 -> CHILLAN VIEJO | F40: ='2025'!I42 -> 0 | G40: ='2025'!#REF! -> #REF! | H40: ='2025'!M42 -> FEMENINO | I40: ='2025'!N42 -> 3290
A41: ='2025'!A44 -> 41 | B41: ='2025'!E43 -> 0 | C41: ='2025'!F43 -> 0 | D41: si | E41: ='2025'!G43 -> CHILLAN | F41: ='2025'!I43 -> 0 | G41: ='2025'!B43 -> 45909 | H41: ='2025'!M43 -> FEMENINO | I41: ='2025'!N43 -> 3535
A42: ='2025'!A45 -> 42 | B42: ='2025'!E44 -> 0 | C42: ='2025'!F44 -> 0 | D42: si | E42: ='2025'!G44 -> CHILLAN | F42: ='2025'!I44 -> 0 | G42: ='2025'!B44 -> 45909 | H42: ='2025'!M44 -> MASCULINO | I42: ='2025'!N44 -> 3720
A43: ='2025'!A46 -> 43 | B43: ='2025'!E45 -> 0 | C43: ='2025'!F45 -> 0 | D43: si | E43: ='2025'!G45 -> COIHUECO | F43: ='2025'!I45 -> 0 | G43: ='2025'!B45 -> 45910 | H43: ='2025'!M45 -> MASCULINO | I43: ='2025'!N45 -> 4190
A44: ='2025'!A47 -> 44 | B44: ='2025'!E46 -> 0 | C44: ='2025'!F46 -> 0 | D44: si | E44: ='2025'!G46 -> EL CARMEN | F44: ='2025'!I46 -> 0 | G44: ='2025'!B46 -> 45910 | H44: ='2025'!M46 -> MASCULINO | I44: ='2025'!N46 -> 4260
A45: ='2025'!A48 -> 45 | B45: ='2025'!E47 -> 0 | C45: ='2025'!F47 -> 0 | D45: si | E45: ='2025'!G47 -> CHILLAN | F45: ='2025'!I47 -> 0 | G45: ='2025'!B47 -> 45910 | H45: ='2025'!M47 -> MASCULINO | I45: ='2025'!N47 -> 3330
A46: ='2025'!A49 -> 46 | B46: ='2025'!E48 -> 0 | C46: ='2025'!F48 -> 0 | D46: si | E46: ='2025'!G48 -> BULNES | F46: ='2025'!I48 -> 0 | G46: ='2025'!B48 -> 45910 | H46: ='2025'!M48 -> FEMENINO | I46: ='2025'!N48 -> 3110
A47: ='2025'!A50 -> 47 | B47: ='2025'!E49 -> 0 | C47: ='2025'!F49 -> 0 | D47: si | E47: ='2025'!G49 -> YUNGAY | F47: ='2025'!I49 -> 0 | G47: ='2025'!B49 -> 45910 | H47: ='2025'!M49 -> FEMENINO | I47: ='2025'!N49 -> 4070
A48: ='2025'!A51 -> 48 | B48: ='2025'!E50 -> 0 | C48: ='2025'!F50 -> 0 | D48: si | E48: ='2025'!G50 -> CHILLAN | F48: ='2025'!I50 -> 0 | G48: ='2025'!C53 -> 0.42152778 | H48: ='2025'!M50 -> MASCULINO | I48: ='2025'!N50 -> 2940
A49: ='2025'!A52 -> 49 | B49: ='2025'!E51 -> 0 | C49: ='2025'!F51 -> 0 | D49: si | E49: ='2025'!G51 -> CHILLAN | F49: ='2025'!I51 -> 0 | G49: ='2025'!B51 -> 45910 | H49: ='2025'!M51 -> FEMENINO | I49: ='2025'!N51 -> 2180
A50: ='2025'!A53 -> 50 | B50: ='2025'!E52 -> 0 | C50: ='2025'!F52 -> 0 | D50: si | E50: ='2025'!G53 -> BULNES | F50: ='2025'!I52 -> 0 | G50: ='2025'!B52 -> 45910 | H50: ='2025'!M52 -> MASCULINO | I50: ='2025'!N52 -> 1878
A51: ='2025'!A54 -> 51 | B51: ='2025'!E53 -> 0 | C51: ='2025'!F53 -> 0 | D51: si | E51: ='2025'!#REF! -> #REF! | F51: ='2025'!I53 -> 0 | G51: ='2025'!B53 -> 45911 | H51: ='2025'!M53 -> MASCULINO | I51: ='2025'!N53 -> 3567
A52: ='2025'!A55 -> 52 | B52: ='2025'!E54 -> 0 | C52: ='2025'!F54 -> 0 | D52: si | E52: ='2025'!G54 -> EL CARMEN | F52: ='2025'!I54 -> 0 | G52: ='2025'!B54 -> 45911 | H52: ='2025'!M54 -> FEMENINO | I52: ='2025'!N54 -> 3880
A53: ='2025'!#REF! -> #REF! | B53: ='2025'!E55 -> 0 | C53: ='2025'!F55 -> 0 | D53: si | E53: ='2025'!G55 -> CHILLAN | F53: ='2025'!I55 -> 0 | G53: ='2025'!B55 -> 45911 | H53: ='2025'!M55 -> FEMENINO | I53: ='2025'!N55 -> 2900
A54: ='2025'!A56 -> 53 | B54: ='2025'!#REF! -> #REF! | C54: ='2025'!#REF! -> #REF! | D54: si | E54: ='2025'!#REF! -> #REF! | F54: ='2025'!#REF! -> #REF! | G54: ='2025'!#REF! -> #REF! | H54: ='2025'!#REF! -> #REF! | I54: ='2025'!#REF! -> #REF!
A55: ='2025'!A57 -> 54 | B55: ='2025'!E56 -> 0 | C55: ='2025'!F56 -> 0 | D55: si | E55: ='2025'!G56 -> CHILLAN | F55: ='2025'!I56 -> 0 | G55: ='2025'!B56 -> 45911 | H55: ='2025'!M56 -> MASCULINO | I55: ='2025'!N56 -> 3890
A56: ='2025'!A58 -> 55 | B56: ='2025'!E57 -> 0 | C56: ='2025'!F57 -> 0 | D56: si | E56: ='2025'!G57 -> SAN IGNACIO | F56: ='2025'!I57 -> 0 | G56: ='2025'!B57 -> 45911 | H56: ='2025'!M57 -> MASCULINO | I56: ='2025'!N57 -> 3030
A57: ='2025'!A59 -> 56 | B57: ='2025'!E58 -> 0 | C57: ='2025'!F58 -> 0 | D57: si | E57: ='2025'!G58 -> YUNGAY | F57: ='2025'!I58 -> 0 | G57: ='2025'!B58 -> 45911 | H57: ='2025'!M58 -> FEMENINO | I57: ='2025'!N58 -> 2810
A58: ='2025'!A60 -> 57 | B58: ='2025'!E59 -> 0 | C58: ='2025'!F59 -> 0 | D58: si | E58: ='2025'!G59 -> CHILLAN VIEJO | F58: ='2025'!I59 -> 0 | G58: ='2025'!B59 -> 45912 | H58: ='2025'!M59 -> FEMENINO | I58: ='2025'!N59 -> 3910
A59: ='2025'!A61 -> 58 | B59: ='2025'!E60 -> 0 | C59: ='2025'!F60 -> 0 | D59: si | E59: ='2025'!G60 -> CHILLAN | F59: ='2025'!I60 -> 0 | G59: ='2025'!B60 -> 45912 | H59: ='2025'!M60 -> FEMENINO | I59: ='2025'!N60 -> 3030
...

Sheet BCG
A1: VACUNA BCG
A2: N° | B2: NOMBRE COMPLETO MADRE DE RN | C2: RUT | D2: si/no | E2: Comuna | F2: Fecha Nacimiento Madre | G2: Fecha Nacimiento Hijo | H2: Sexo | I2: Peso | J2: Reacción Adversa | K2: N° Cama
A3: ='2025'!A4 -> 1 | B3: ='2025'!E4 -> 0 | C3: ='2025'!F4 -> 0 | D3: SI | E3: ='2025'!G4 -> CHILLAN VIEJO | F3: ='2025'!I4 -> 0 | G3: ='2025'!B4 -> 45901 | H3: ='2025'!M4 -> FEMENINO | I3: ='2025'!N4 -> 3450 | K3: ='2025'!AR4 -> RECUPERACION
A4: ='2025'!A5 -> 2 | B4: ='2025'!E5 -> 0 | C4: ='2025'!F5 -> 0 | D4: SI | E4: ='2025'!G5 -> CHILLAN | F4: ='2025'!I5 -> 0 | G4: ='2025'!B5 -> 45901 | H4: ='2025'!M5 -> FEMENINO | I4: ='2025'!N5 -> 3350 | K4: ='2025'!AR5 -> RECUPERACION
A5: ='2025'!A6 -> 3 | B5: ='2025'!E6 -> 0 | C5: ='2025'!F6 -> 0 | D5: SI | E5: ='2025'!G6 -> CHILLAN | F5: ='2025'!I6 -> 0 | G5: ='2025'!B6 -> 45901 | H5: ='2025'!M6 -> MASCULINO | I5: ='2025'!N6 -> 3270 | K5: ='2025'!AR6 -> TIM NEO
A6: ='2025'!A7 -> 4 | B6: ='2025'!E7 -> 0 | C6: ='2025'!F7 -> 0 | D6: SI | E6: ='2025'!G7 -> CHILLAN | F6: ='2025'!I7 -> 0 | G6: ='2025'!B7 -> 45901 | H6: ='2025'!M7 -> MASCULINO | I6: ='2025'!N7 -> 2470 | K6: ='2025'!AR7 -> RECUPERACION
A7: ='2025'!A8 -> 5 | B7: ='2025'!E8 -> 0 | C7: ='2025'!F8 -> 0 | D7: SI | E7: ='2025'!G8 -> PORTEZUELO | F7: ='2025'!I8 -> 0 | G7: ='2025'!B8 -> 45902 | H7: ='2025'!M8 -> FEMENINO | I7: ='2025'!N8 -> 4030 | K7: ='2025'!AR8 -> SALA
A8: ='2025'!A9 -> 6 | B8: ='2025'!E9 -> 0 | C8: ='2025'!F9 -> 0 | D8: SI | E8: ='2025'!G9 -> SAN IGNACIO | F8: ='2025'!I9 -> 0 | G8: ='2025'!B9 -> 45902 | H8: ='2025'!M9 -> FEMENINO | I8: ='2025'!N9 -> 3660 | K8: ='2025'!AR9 -> SALA
A9: ='2025'!A10 -> 7 | B9: ='2025'!E10 -> 0 | C9: ='2025'!F10 -> 0 | D9: SI | E9: ='2025'!G10 -> CHILLAN | F9: ='2025'!I10 -> 0 | G9: ='2025'!B10 -> 45902 | H9: ='2025'!M10 -> MASCULINO | I9: ='2025'!N10 -> 2410 | K9: ='2025'!AR10 -> SALA
A10: ='2025'!A11 -> 8 | B10: ='2025'!E11 -> 0 | C10: ='2025'!F11 -> 0 | D10: SI | E10: ='2025'!G11 -> CHILLAN | F10: ='2025'!I11 -> 0 | G10: ='2025'!B11 -> 45903 | H10: ='2025'!M11 -> MASCULINO | I10: ='2025'!N11 -> 3875 | K10: ='2025'!AR11 -> SALA
A11: ='2025'!A12 -> 9 | B11: ='2025'!E12 -> 0 | C11: ='2025'!F12 -> 0 | D11: NO | E11: ='2025'!G12 -> BULNES | F11: ='2025'!I12 -> 0 | G11: ='2025'!B12 -> 45903 | H11: ='2025'!M12 -> FEMENINO | I11: ='2025'!N12 -> 3820 | K11: ='2025'!AR12 -> RECUPERACION
A12: ='2025'!A13 -> 10 | B12: ='2025'!E13 -> 0 | C12: ='2025'!F13 -> 0 | D12: SI | E12: ='2025'!G13 -> QUILLON | F12: ='2025'!I13 -> 0 | G12: ='2025'!B13 -> 45903 | H12: ='2025'!M13 -> MASCULINO | I12: ='2025'!N13 -> 3310 | K12: ='2025'!AR13 -> SALA
A13: ='2025'!A14 -> 11 | B13: ='2025'!E14 -> 0 | C13: ='2025'!F14 -> 0 | D13: SI | E13: ='2025'!G14 -> COIHUECO | F13: ='2025'!I14 -> 0 | G13: ='2025'!B14 -> 45903 | H13: ='2025'!M14 -> MASCULINO | I13: ='2025'!N14 -> 3330 | K13: ='2025'!AR14 -> SALA
A14: ='2025'!A15 -> 12 | B14: ='2025'!E15 -> 0 | C14: ='2025'!F15 -> 0 | D14: SI | E14: ='2025'!G15 -> YUNGAY | F14: ='2025'!I15 -> 0 | G14: ='2025'!B15 -> 45904 | H14: ='2025'!M15 -> MASCULINO | I14: ='2025'!N15 -> 2350 | K14: ='2025'!AR15 -> RECUPERACION
... A27: ='2025'!A28 -> 25 | B27: ='2025'!E28 -> 0 | C27: ='2025'!F28 -> 0 | D27: si | E27: ='2025'!G28 -> BULNES | F27: ='2025'!I28 -> 0 | G27: ='2025'!B28 -> 45783 | H27: ='2025'!M28 -> FEMENINO | I27: ='2025'!N28 -> 2820 | K27: ='2025'!AR28 -> SALA
A28: ='2025'!#REF! -> #REF! | B28: ='2025'!#REF! -> #REF! | C28: ='2025'!#REF! -> #REF! | E28: ='2025'!#REF! -> #REF! | F28: ='2025'!#REF! -> #REF! | G28: ='2025'!#REF! -> #REF! | H28: ='2025'!#REF! -> #REF! | I28: ='2025'!#REF! -> #REF! | K28: ='2025'!#REF! -> #REF!
A29: ='2025'!A30 -> 27 | B29: ='2025'!E30 -> 0 | C29: ='2025'!F30 -> 0 | E29: ='2025'!G30 -> CHILLAN | F29: ='2025'!I30 -> 0 | G29: ='2025'!B30 -> 45907 | H29: ='2025'!M30 -> MASCULINO | I29: ='2025'!N30 -> 4170 | K29: ='2025'!AR30 -> RECUPERACION
A30: ='2025'!A31 -> 28 | B30: ='2025'!E31 -> 0 | C30: ='2025'!F31 -> 0 | E30: ='2025'!G31 -> RANQUIL | F30: ='2025'!I31 -> 0 | G30: ='2025'!B31 -> 45907 | H30: ='2025'!M31 -> FEMENINO | I30: ='2025'!N31 -> 2780 | K30: ='2025'!AR31 -> SALA
A31: ='2025'!A32 -> 29 | B31: ='2025'!E32 -> 0 | C31: ='2025'!F32 -> 0 | E31: ='2025'!G32 -> CHILLAN | F31: ='2025'!I32 -> 0 | G31: ='2025'!B32 -> 45908 | H31: ='2025'!M32 -> MASCULINO | I31: ='2025'!N32 -> 3235 | K31: ='2025'!AR32 -> SALA
A32: ='2025'!A33 -> 30 | B32: ='2025'!E33 -> 0 | C32: ='2025'!F33 -> 0 | E32: ='2025'!G33 -> CHILLAN | F32: ='2025'!I33 -> 0 | G32: ='2025'!B33 -> 45908 | H32: ='2025'!M33 -> FEMENINO | I32: ='2025'!N33 -> 3280 | K32: ='2025'!AR33 -> SALA
A33: ='2025'!A34 -> 31 | B33: ='2025'!E34 -> 0 | C33: ='2025'!F34 -> 0 | E33: ='2025'!G34 -> QUIRIHUE | F33: ='2025'!I34 -> 0 | G33: ='2025'!B34 -> 45908 | H33: ='2025'!M34 -> FEMENINO | I33: ='2025'!N34 -> 3960 | K33: ='2025'!AR34 -> RECUPERACION
A34: ='2025'!A29 -> 26 | B34: ='2025'!E29 -> 0 | C34: ='2025'!F29 -> 0 | E34: ='2025'!G29 -> CHILLAN | F34: ='2025'!I29 -> 0 | G34: ='2025'!B29 -> 45906 | H34: ='2025'!M29 -> MASCULINO | I34: ='2025'!N29 -> 2580 | K34: ='2025'!AR29 -> SALA
A35: ='2025'!#REF! -> #REF! | B35: ='2025'!E36 -> 0 | C35: ='2025'!F36 -> 0 | E35: ='2025'!G36 -> PUEBLO SECO | F35: ='2025'!I36 -> 0 | G35: ='2025'!B36 -> 45908 | H35: ='2025'!M36 -> MASCULINO | I35: ='2025'!N36 -> 3660 | K35: ='2025'!AR36 -> SALA
A36: ='2025'!A39 -> 36 | B36: ='2025'!#REF! -> #REF! | C36: ='2025'!#REF! -> #REF! | E36: ='2025'!#REF! -> #REF! | F36: ='2025'!#REF! -> #REF! | G36: ='2025'!#REF! -> #REF! | H36: ='2025'!#REF! -> #REF! | I36: ='2025'!#REF! -> #REF! | K36: ='2025'!#REF! -> #REF!
A37: ='2025'!A40 -> 37 | B37: ='2025'!E39 -> 0 | C37: ='2025'!F39 -> 0 | E37: ='2025'!G39 -> CHILLAN | F37: ='2025'!I39 -> 0 | G37: ='2025'!B39 -> 45908 | H37: ='2025'!M39 -> MASCULINO | I37: ='2025'!N39 -> 880 | K37: ='2025'!AR39 -> UCI
A38: ='2025'!A41 -> 38 | B38: ='2025'!E40 -> 0 | C38: ='2025'!F40 -> 0 | E38: ='2025'!G40 -> CHILLAN | F38: ='2025'!I40 -> 0 | G38: ='2025'!B40 -> 45909 | H38: ='2025'!M40 -> FEMENINO | I38: ='2025'!N40 -> 3080 | K38: ='2025'!AR40 -> SALA
A39: ='2025'!A42 -> 39 | B39: ='2025'!E41 -> 0 | C39: ='2025'!F41 -> 0 | E39: ='2025'!G41 -> YUNGAY | F39: ='2025'!I41 -> 0 | G39: ='2025'!B42 -> 45909 | H39: ='2025'!M41 -> MASCULINO | I39: ='2025'!N41 -> 2650 | K39: ='2025'!AR41 -> SALA
A40: ='2025'!A43 -> 40 | B40: ='2025'!E42 -> 0 | C40: ='2025'!F42 -> 0 | E40: ='2025'!G42 -> CHILLAN VIEJO | F40: ='2025'!I42 -> 0 | G40: ='2025'!#REF! -> #REF! | H40: ='2025'!M42 -> FEMENINO | I40: ='2025'!N42 -> 3290 | K40: ='2025'!AR42 -> RECUPERACION
A41: ='2025'!A44 -> 41 | B41: ='2025'!E43 -> 0 | C41: ='2025'!F43 -> 0 | E41: ='2025'!G43 -> CHILLAN | F41: ='2025'!I43 -> 0 | G41: ='2025'!B43 -> 45909 | H41: ='2025'!M43 -> FEMENINO | I41: ='2025'!N43 -> 3535 | K41: ='2025'!AR43 -> SALA
A42: ='2025'!A45 -> 42 | B42: ='2025'!E44 -> 0 | C42: ='2025'!F44 -> 0 | E42: ='2025'!G44 -> CHILLAN | F42: ='2025'!I44 -> 0 | G42: ='2025'!B44 -> 45909 | H42: ='2025'!M44 -> MASCULINO | I42: ='2025'!N44 -> 3720 | K42: ='2025'!AR44 -> SALA
A43: ='2025'!A46 -> 43 | B43: ='2025'!E45 -> 0 | C43: ='2025'!F45 -> 0 | E43: ='2025'!G45 -> COIHUECO | F43: ='2025'!I45 -> 0 | G43: ='2025'!B45 -> 45910 | H43: ='2025'!M45 -> MASCULINO | I43: ='2025'!N45 -> 4190 | K43: ='2025'!AR45 -> SALA
A44: ='2025'!A47 -> 44 | B44: ='2025'!E46 -> 0 | C44: ='2025'!F46 -> 0 | E44: ='2025'!G46 -> EL CARMEN | F44: ='2025'!I46 -> 0 | G44: ='2025'!B46 -> 45910 | H44: ='2025'!M46 -> MASCULINO | I44: ='2025'!N46 -> 4260 | K44: ='2025'!AR46 -> TIM NEO
A45: ='2025'!A49 -> 46 | B45: ='2025'!E48 -> 0 | C45: ='2025'!F48 -> 0 | E45: ='2025'!G48 -> BULNES | F45: ='2025'!I48 -> 0 | G45: ='2025'!B48 -> 45910 | H45: ='2025'!M48 -> FEMENINO | I45: ='2025'!N48 -> 3110 | K45: ='2025'!AR48 -> SALA
A47: ='2025'!A50 -> 47 | B47: ='2025'!E49 -> 0 | C47: ='2025'!F49 -> 0 | E47: ='2025'!G49 -> YUNGAY | F47: ='2025'!I49 -> 0 | G47: ='2025'!B49 -> 45910 | H47: ='2025'!M49 -> FEMENINO | I47: ='2025'!N49 -> 4070 | K47: ='2025'!AR49 -> RECUPERACION
A48: ='2025'!A51 -> 48 | B48: ='2025'!E50 -> 0 | C48: ='2025'!F50 -> 0 | E48: ='2025'!G50 -> CHILLAN | F48: ='2025'!I50 -> 0 | G48: ='2025'!C53 -> 0.42152778 | H48: ='2025'!M50 -> MASCULINO | I48: ='2025'!N50 -> 2940 | K48: ='2025'!AR50 -> RECUPERACION
A49: ='2025'!A52 -> 49 | B49: ='2025'!E51 -> 0 | C49: ='2025'!F51 -> 0 | E49: ='2025'!G51 -> CHILLAN | F49: ='2025'!I51 -> 0 | G49: ='2025'!B51 -> 45910 | H49: ='2025'!M51 -> FEMENINO | I49: ='2025'!N51 -> 2180 | K49: ='2025'!AR51 -> RECUPERACION
A50: ='2025'!A53 -> 50 | B50: ='2025'!E53 -> 0 | C50: ='2025'!F53 -> 0 | E50: ='2025'!#REF! -> #REF! | F50: ='2025'!I53 -> 0 | G50: ='2025'!B53 -> 45911 | H50: ='2025'!M53 -> MASCULINO | I50: ='2025'!N53 -> 3567 | K50: ='2025'!AR53 -> RECUPERACION
A51: ='2025'!A54 -> 51
A52: ='2025'!A55 -> 52 | C52: ='2025'!F54 -> 0 | E52: ='2025'!G54 -> EL CARMEN | F52: ='2025'!I54 -> 0 | G52: ='2025'!B54 -> 45911 | H52: ='2025'!M54 -> FEMENINO | I52: ='2025'!N54 -> 3880 | K52: ='2025'!AR54 -> RECUPERACION
A53: ='2025'!#REF! -> #REF! | B53: ='2025'!E55 -> 0 | C53: ='2025'!F55 -> 0 | E53: ='2025'!G55 -> CHILLAN | F53: ='2025'!I55 -> 0 | G53: ='2025'!B55 -> 45911 | H53: ='2025'!M55 -> FEMENINO | I53: ='2025'!N55 -> 2900 | K53: ='2025'!AR55 -> SALA
...

Sheet REM
A1: SECCIÓN D: INFORMACIÓN DE RECIÉN NACIDOS
A2: SECCIÓN D.1: INFORMACION GENERAL DE RECIEN NACIDOS VIVOS
A3: TIPO | C3: TOTAL | D3: PESO AL NACER (EN GRAMOS) | L3: Anomalía Congénita | M3: REM A 24
D4: Menos de 500 | E4: 500 a 999 | F4: 1.000 a 1.499 | G4: 1.500 a 1.999 | H4: 2.000 a 2.499 | I4: 2.500 a 2.999 | J4: 3.000 a 3.999 | K4: 4.000 y más
A5: NACIDOS VIVOS | C5: =SUM(D5:K5) -> 143 | D5: =COUNTIFS('2025'!N:N, "<500",'2025'!N:N, ">250") -> 0 | E5: =COUNTIFS('2025'!N:N, "<1000",'2025'!N:N, ">499") -> 2 | F5: =COUNTIFS('2025'!N:N, "<1500",'2025'!N:N, ">999") -> 2 | G5: =COUNTIFS('2025'!N:N, "<2000",'2025'!N:N, ">1499") -> 4 | H5: 16 | I5: =COUNTIFS('2025'!N:N, "<3000",'2025'!N:N, ">2499") -> 23 | J5: =COUNTIFS('2025'!N:N, "<4000",'2025'!N:N, ">2999") -> 82 | K5: =COUNTIFS('2025'!N:N, "<5500",'2025'!N:N, ">3999") -> 14 | L5: =COUNTIF('2025'!AO:AO, "SI") -> 1 | CA5: =IF(DA5=1,"* Total Nacidos Vivos con Anomalía Congénita NO DEBE ser MAYOR a Nacidos Vivos según peso al Nacer. ","")
A6: SECCIÓN D.2: ATENCION INMEDIATA DEL RECIEN NACIDO | H6: =COUNTIFS('2025'!N:N, "<2500",'2025'!N:N, ">1999") -> 17
A7: TIPO | C7: PROFILAXIS | E7: TIPO DE PARTO | I7: APGAR | K7: Reanimación Básica | L7: Reanimación Avanzada | M7: EHI Grado II y III | N7: REM A 24
C8: Hepatitis B | D8: Ocular | E8: Parto Vaginal | F8: Parto Instrumental | G8: Cesárea | H8: Parto extrahospitalario | I8: Apgar menor o igual a 3 al minuto | J8: Apgar menor o igual a 6 a los 5 minutos
A9: NACIDOS VIVOS | C9: =COUNTIF('2025'!T:T,"SI") -> 143 | D9: =COUNTIF('2025'!S:S,"SI") -> 143 | E9: =COUNTIF('2025'!J:J, "EUTOCICO") -> 73 | F9: =E12+E13 -> 4 | G9: =H12+H13 -> 66 | H9: 0 | I9: =COUNTIF('2025'!W:W, "<4") -> 3 | J9: =COUNTIF('2025'!X:X, "<7") -> 3 | K9: =COUNTIF('2025'!Y:Y, "SI") -> 16 | L9: =COUNTIF('2025'!Z:Z, "SI") -> 6
D12: DISTOCICO | E12: =COUNTIFS('2025'!J:J,"DISTOCICO") -> 1 | G12: C. URGENCIA | H12: =COUNTIF('2025'!J:J, "CESAREA URGENCIA") -> 39
D13: VACUUM | E13: =COUNTIFS('2025'!J:J,"VACUUM") -> 3 | G13: C. ELECTIVA | H13: =COUNTIF('2025'!J:J, "CESAREA ELECTIVA") -> 27
D15: TOTAL DE PARTOS | F15: =SUM(E9:G9) -> 143
A18: SECCION D: APLICACIÓN DE PROFILAXIS OCULAR PARA GONORREA EN RECIEN NACIDOS
B19: Total | C19: Pueblos Originarios | D19: Migrantes | E19: REM A11
A20: Recién Nacidos vivos que reciben profilaxis ocular para gonorrea al nacer | B20: =COUNTIF('2025'!S:S, "SI") -> 143 | C20: =COUNTIFS('2025'!S:S,"SI",'2025'!AM:AM,"SI") -> 0 | D20: =COUNTIFS('2025'!S:S, "SI",'2025'!AL:AL, "SI") -> 7 | CA20: =IF(AND($B20<>0,C20=""),"* No olvide ingresar la columna Pueblos Originarios (Digite CERO si no tiene). ",IF(C20>$B20,"* El Número de recién nacidos pertenecientes a Pueblos Originarios no puede superar el Total. ","")) | CB20: =IF(AND($B20<>0,D20=""),"* No olvide ingresar la columna Migrantes (Digite CERO si no tiene). ",IF(D20>$B20,"* El Número de recién nacidos en tratamiento pertenecientes a Población Migrante no puede superar el Total. ","")) | CG20: =IF(AND($B20<>0,C20=""),1,IF(C20>$B20,1,0)) -> 0 | CH20: =IF(AND($B20<>0,D20=""),1,IF(D20>$B20,1,0)) -> 0
A21: Recién nacidos vivos | B21: =C5 -> 143 | C21: =COUNTIFS('2025'!AM:AM,"SI") -> 0 | D21: =COUNTIF('2025'!AL:AL, "SI") -> 7 | CA21: =IF(AND($B21<>0,C21=""),"* No olvide ingresar la columna Pueblos Originarios (Digite CERO si no tiene). ",IF(C21>$B21,"* El Número de recién nacidos pertenecientes a Pueblos Originarios no puede superar el Total. ","")) | CB21: =IF(AND($B21<>0,D21=""),"* No olvide ingresar la columna Migrantes (Digite CERO si no tiene). ",IF(D21>$B21,"* El Número de recién nacidos en tratamiento pertenecientes a Población Migrante no puede superar el Total. ","")) | CG21: =IF(AND($B21<>0,C21=""),1,IF(C21>$B21,1,0)) -> 0 | CH21: =IF(AND($B21<>0,D21=""),1,IF(D21>$B21,1,0)) -> 0
A24: SECCION J: PROFILAXIS DE TRANSMISIÓN VERTICAL APLICADA AL RECIEN NACIDO, HIJO DE MADRE HEPATITIS B POSITIVA
B25: Total | C25: Pueblos Originarios | D25: Migrantes | E25: REM A11
A26: Recién nacidos hijos de madre Hepatitis B positiva, nacidos en el periodo | B26: =COUNTIF('2025'!AI:AI, "POSITIVO") -> 0 | C26: =COUNTIFS('2025'!AI:AI,"POSITIVO",'2025'!AM:AM, "SI") -> 0 | D26: =COUNTIFS('2025'!AI:AI,"POSITIVO",'2025'!AL:AL, "SI") -> 0 | CA26: =IF(AND($B26<>0,C26=""),"* No olvide ingresar la columna Pueblos Originarios (Digite CERO si no tiene). ",IF(C26>$B26,"* El Número de recién nacidos pertenecientes a Pueblos Originarios no puede superar el Total. ","")) | CB26: =IF(AND($B26<>0,D26=""),"* No olvide ingresar la columna Migrantes (Digite CERO si no tiene). ",IF(D26>$B26,"* El Número de recién nacidos en tratamiento pertenecientes a Población Migrante no puede superar el Total. ","")) | CG26: =IF(AND($B26<>0,C26=""),1,IF(C26>$B26,1,0)) -> 0 | CH26: =IF(AND($B26<>0,D26=""),1,IF(D26>$B26,1,0)) -> 0
A27: Recién nacidos hijos de madre Hepatitis B positiva que recibieron profilaxis completa, según la normativa vigente | B27: =COUNTIF('2025'!AJ:AJ, "SI") -> 0 | C27: =COUNTIFS('2025'!AJ:AJ,"SI",'2025'!AM:AM, "SI") -> 0 | D27: =COUNTIFS('2025'!AJ:AJ,"SI",'2025'!AL:AL, "SI") -> 0 | CA27: =IF(AND($B27<>0,C27=""),"* No olvide ingresar la columna Pueblos Originarios (Digite CERO si no tiene). ",IF(C27>$B27,"* El Número de recién nacidos pertenecientes a Pueblos Originarios no puede superar el Total. ","")) | CB27: =IF(AND($B27<>0,D27=""),"* No olvide ingresar la columna Migrantes (Digite CERO si no tiene). ",IF(D27>$B27,"* El Número de recién nacidos en tratamiento pertenecientes a Población Migrante no puede superar el Total. ","")) | CG27: =IF(AND($B27<>0,C27=""),1,IF(C27>$B27,1,0)) -> 0 | CH27: =IF(AND($B27<>0,D27=""),1,IF(D27>$B27,1,0)) -> 0
A30: CARACTERISTICAS DEL PARTO | C30: Lactancia materna en los primeros 60 minutos de vida (RN con peso de 2.500 grs. o más) | E30: REM 24
A33: TOTAL PARTOS | C33: =SUM(C34:C37) -> 122
A34: VAGINAL | C34: =COUNTIFS('2025'!R:R, "SI",'2025'!J:J, "EUTOCICO") -> 65
A35: INSTRUMENTAL | C35: =COUNTIFS('2025'!R:R, "SI",'2025'!J:J, "CESAREA DISTOCICO") -> 0
A36: CESÁREA ELECTIVA | C36: =COUNTIFS('2025'!R:R, "SI",'2025'!J:J,"CESAREA ELECTIVA") -> 26
A37: CESÁREA URGENCIA | C37: =COUNTIFS('2025'!R:R, "SI",'2025'!J:J, "CESAREA URGENCIA") -> 31
